2022-12-14 16:03:52,393 ERROR Internal Server Error: /news/9 /Users/perevazko/PycharmProjects/NewsPortal/venv/lib/python3.9/site-packages/django/utils/log.py (<class 'django.core.exceptions.FieldError'>, FieldError("Cannot resolve keyword 'name' into field. Choices are: author, author_id, category, categoryType, comment, dateCreation, id, image, postcategory, rating, text, title"), <traceback object at 0x7fda4fcd9080>)
Traceback (most recent call last):
  File "/Users/perevazko/PycharmProjects/NewsPortal/venv/lib/python3.9/site-packages/django/core/handlers/exception.py", line 55, in inner
    response = get_response(request)
  File "/Users/perevazko/PycharmProjects/NewsPortal/venv/lib/python3.9/site-packages/django/core/handlers/base.py", line 197, in _get_response
    response = wrapped_callback(request, *callback_args, **callback_kwargs)
  File "/Users/perevazko/PycharmProjects/NewsPortal/venv/lib/python3.9/site-packages/django/views/generic/base.py", line 103, in view
    return self.dispatch(request, *args, **kwargs)
  File "/Users/perevazko/PycharmProjects/NewsPortal/venv/lib/python3.9/site-packages/django/views/generic/base.py", line 142, in dispatch
    return handler(request, *args, **kwargs)
  File "/Users/perevazko/PycharmProjects/NewsPortal/venv/lib/python3.9/site-packages/django/views/generic/detail.py", line 109, in get
    context = self.get_context_data(object=self.object)
  File "/Users/perevazko/PycharmProjects/NewsPortal/news/simpleapp/views.py", line 56, in get_context_data
    news = get_object_or_404(News, name=self.kwargs["pk"])
  File "/Users/perevazko/PycharmProjects/NewsPortal/venv/lib/python3.9/site-packages/django/shortcuts.py", line 85, in get_object_or_404
    return queryset.get(*args, **kwargs)
  File "/Users/perevazko/PycharmProjects/NewsPortal/venv/lib/python3.9/site-packages/django/db/models/query.py", line 636, in get
    clone = self._chain() if self.query.combinator else self.filter(*args, **kwargs)
  File "/Users/perevazko/PycharmProjects/NewsPortal/venv/lib/python3.9/site-packages/django/db/models/query.py", line 1420, in filter
    return self._filter_or_exclude(False, args, kwargs)
  File "/Users/perevazko/PycharmProjects/NewsPortal/venv/lib/python3.9/site-packages/django/db/models/query.py", line 1438, in _filter_or_exclude
    clone._filter_or_exclude_inplace(negate, args, kwargs)
  File "/Users/perevazko/PycharmProjects/NewsPortal/venv/lib/python3.9/site-packages/django/db/models/query.py", line 1445, in _filter_or_exclude_inplace
    self._query.add_q(Q(*args, **kwargs))
  File "/Users/perevazko/PycharmProjects/NewsPortal/venv/lib/python3.9/site-packages/django/db/models/sql/query.py", line 1532, in add_q
    clause, _ = self._add_q(q_object, self.used_aliases)
  File "/Users/perevazko/PycharmProjects/NewsPortal/venv/lib/python3.9/site-packages/django/db/models/sql/query.py", line 1562, in _add_q
    child_clause, needed_inner = self.build_filter(
  File "/Users/perevazko/PycharmProjects/NewsPortal/venv/lib/python3.9/site-packages/django/db/models/sql/query.py", line 1407, in build_filter
    lookups, parts, reffed_expression = self.solve_lookup_type(arg)
  File "/Users/perevazko/PycharmProjects/NewsPortal/venv/lib/python3.9/site-packages/django/db/models/sql/query.py", line 1217, in solve_lookup_type
    _, field, _, lookup_parts = self.names_to_path(lookup_splitted, self.get_meta())
  File "/Users/perevazko/PycharmProjects/NewsPortal/venv/lib/python3.9/site-packages/django/db/models/sql/query.py", line 1709, in names_to_path
    raise FieldError(
django.core.exceptions.FieldError: Cannot resolve keyword 'name' into field. Choices are: author, author_id, category, categoryType, comment, dateCreation, id, image, postcategory, rating, text, title
2022-12-14 16:03:52,415 ERROR "GET /news/9 HTTP/1.1" 500 132906 /Users/perevazko/PycharmProjects/NewsPortal/venv/lib/python3.9/site-packages/django/core/servers/basehttp.py None
